Workbook

Sheet Accueil
A1: Système convolutif — rapports non typiques
A2: Cadre paramétrique validé sur le rapport 1/3; les autres rapports exigent leurs propres termes et paramètres avant une preuve de couverture universelle.
A4: CONTENU
A5: Exemple 1-3 | B5: Feuille originale conservée, avec les suites A et B fournies.
A6: Parametres | B6: Règle active par rapport : k, n, exposant de reconstruction et Digamma.
A7: Convolution | B7: Termes formels signés évalués numériquement à partir de k.
A8: Tests Digamma | B8: Quatre possibilités : positions 7 ou 8, signes − ou +.
A9: Moteur Universel | B9: Entrées k/n, construction A/B, sommes fermées et quatre essais Digamma.
A10: Modèle Formel | B10: Moteur vierge universel : saisie de k et n, substitution et quatre candidats Digamma.
A11: Démonstration Formelle | B11: Preuve symbolique visuelle A₁₀/A₉, B₁₀/B₉, Digamma et reconstruction pour tout 1/k.
A12: Rapport | B12: 1/3
A13: Sommes | B13: A = 79 824; B = 238 746
A14: Digamma | B14: position 8, signe −
A15: Premier reconstruit | B15: 227, rang 49

Sheet Exemple 1-3
E9: Table servant a reconstruire le rapport non typique
E10: 1/k | F10: 0 | G10: 1 | H10: 2
E11: 3 | F11: 4 | G11: 5 | H11: 6
E12: 7 | F12: 8 | G12: 9 | H12: 10
C13: t^1+ | D13: t^2+ | E13: t^3+ | F13: t^4+ | G13: t^5+ | H13: t^6+ | I13: t^7+ | J13: t^8+ | K13: (t^9-t^7)+ | L13: (t^10-t^8) | M13: =N13 -> Somme suite A | N13: Somme suite A
C14: t^1+ | D14: t^2+ | E14: t^3+ | F14: t^4+ | G14: t^5+ | H14: t^7+ | I14: t^8+ | J14: t^9+ | K14: (t^10-t^8)+ | L14: (t^11-t^9) | M14: =N14 -> Somme suite B | N14: Somme suite B
C25: Déteminer les suite A et B pour 9 termes
C27: t^1+ | D27: t^2+ | E27: t^3+ | F27: t^4+ | G27: t^5+ | H27: t^6+ | I27: t^7+ | K27: (t^9-t^7)+ | L27: (t^10-t^8) | M27: =N27 -> Somme suite A | N27: Somme suite A
C28: t^1+ | D28: t^2+ | E28: t^3+ | F28: t^4+ | G28: t^5+ | H28: t^7+ | I28: t^8+ | K28: (t^10-t^8)+ | L28: (t^11-t^9) | M28: =N28 -> Somme suite B | N28: Somme suite B
F30: (m13-m27)/t^8= | G30: coefficient A
F31: (m14-m28)/t^8 | G31: coefficient B
J32: =M34 -> 0
F33: Forme des équation générale ((coefficient A/x)*(k^n)-reste | J33: somme suite A
H35: ((coefficient B)/x)*(k^n)-reste | J35: somme suite B

Sheet Parametres
A1: Paramètres des règles
A2: Une ligne par rapport 1/k. Aucun autre rapport n’est inventé : ajoutez ses termes dans Convolution puis ses paramètres ici.
A4: CATALOGUE DES RÈGLES
A5: Rapport | B5: k | C5: n | D5: Exp reconstruction | E5: Position Digamma | F5: Signe Digamma | G5: Statut
A6: 1/3 | B6: 3 | C6: 10 | D6: 6 | E6: 8 | F6: -1 | G6: Validé par exemple fourni
A9: SORTIE DE LA RÈGLE SÉLECTIONNÉE
A10: Rapport | B10: Somme A | C10: Somme B | D10: A ajustée | E10: P reconstruit | F10: Premier? | G10: Rang premier
A11: 1/3 | B11: =SUMIFS(tblConvolution[Valeur],tblConvolution[Rapport],A11,tblConvolution[Suite],"A") -> 79824 | C11: =SUMIFS(tblConvolution[Valeur],tblConvolution[Rapport],A11,tblConvolution[Suite],"B") -> 238746 | D11: =B11+_xlfn.XLOOKUP(A11,tblRegles[Rapport],tblRegles[Signe Digamma])*_xlfn.XLOOKUP(A11,tblRegles[Rapport],tblRegles[k])^_xlfn.XLOOKUP(A11,tblRegles[Rapport],tblRegles[Position Digamma]) -> 73263 | E11: =(C11-D11)/_xlfn.XLOOKUP(A11,tblRegles[Rapport],tblRegles[k])^_xlfn.XLOOKUP(A11,tblRegles[Rapport],tblRegles[Exp reconstruction]) -> 227 | F11: {=_xlfn.LET(_xlpm.p,E11,IF(OR(_xlpm.p<>INT(_xlpm.p),_xlpm.p<2),"Non",IF(SUM(--(MOD(_xlpm.p,_xlfn.SEQUENCE(_xlpm.p))=0))=2,"Oui","Non")))} -> Oui | G11: {=IF(F11<>"Oui","",_xlfn.LET(_xlpm.p,INT(E11),_xlpm.q,_xlfn.SEQUENCE(_xlpm.p),_xlpm.d,TRANSPOSE(_xlfn.SEQUENCE(_xlpm.p)),_xlpm.cnt,MMULT(--(MOD(_xlpm.q,_xlpm.d)=0),_xlfn.SEQUENCE(_xlpm.p,,1,0)),SUM(--(_xlpm.cnt=2))))} -> 49
A12: Obligation universelle | G12: Chaque premier cible doit être produit une fois par le catalogue complet.
A15: CONSTANTES DES SOMMES FERMÉES
A16: k | B16: αA | C16: αB | D16: offset A | E16: offset B | F16: Portée | G16: Statut
A17: 2 | B17: 3.25 | C17: 6.5 | D17: 2 | E17: 66 | F17: 46024 | G17: Fourni
A18: 3 | B18: 8.1111111 | C18: 24.333333 | D18: 1.5 | E18: 730.5 | F18: 46025 | G18: Fourni
A19: 4 | B19: 15.0625 | C19: 60.25 | D19: 1.3333333 | E19: 4097.3333 | F19: 46026 | G19: Fourni
F20: Tout autre 1/k | G20: À compléter
A22: RÈGLES ACTIVES
A23: n ≤ 7 | B23: XIII simple OU XII terminal | C23: A=B | D23: Choix utilisateur
A24: n ≥ 8 | B24: A terminale Savard | C24: B avec saut Zêta i=6 | D24: Digamma: ±A(7), ±A(8) | E24: Dénominateur k^6 | F24: Sélection par essai-erreur

Sheet Moteur Universel
A1: Moteur convolutif universel — rapports non typiques
A2: Construction pour tout k≥2 et n≥1. Les constantes des sommes fermées doivent être renseignées par rapport; le Digamma est testé selon quatre possibilités.
A4: ENTRÉES | G4: RECONSTRUCTION PAR ESSAI-ERREUR
A5: Paramètre | B5: Valeur | G5: Option | H5: Position | I5: Signe | J5: Digamma calculé | K5: P reconstruit | L5: Entier? | M5: Premier?
A6: k | B6: 3 | C6: Entier ≥2 | G6: 1 | H6: 7 | I6: 1 | J6: {=IF($B$7<8,NA(),$B$14+I6*INDEX(_xlfn.ANCHORARRAY($B$19),H6))} -> 82011 | K6: =IFERROR(($C$14-J6)/$B$6^6,NA()) -> 215 | L6: =IFERROR(IF(K6=INT(K6),"Oui","Non"),"Non") -> Oui | M6: {=_xlfn.LET(_xlpm.p,K6,IF(OR(L6<>"Oui",_xlpm.p<2),"Non",IF(_xlpm.p=2,"Oui",IF(MOD(_xlpm.p,2)=0,"Non",_xlfn.LET(_xlpm.m,MAX(1,INT((SQRT(_xlpm.p)-1)/2)),IF(SUM(--(MOD(_xlpm.p,_xlfn.SEQUENCE(_xlpm.m,1,3,2))=0))=0,"Oui","Non"))))))} -> Non
A7: n | B7: 10 | C7: Entier ≥1 | G7: 2 | H7: 7 | I7: -1 | J7: {=IF($B$7<8,NA(),$B$14+I7*INDEX(_xlfn.ANCHORARRAY($B$19),H7))} -> 77637 | K7: =IFERROR(($C$14-J7)/$B$6^6,NA()) -> 221 | L7: =IFERROR(IF(K7=INT(K7),"Oui","Non"),"Non") -> Oui | M7: {=_xlfn.LET(_xlpm.p,K7,IF(OR(L7<>"Oui",_xlpm.p<2),"Non",IF(_xlpm.p=2,"Oui",IF(MOD(_xlpm.p,2)=0,"Non",_xlfn.LET(_xlpm.m,MAX(1,INT((SQRT(_xlpm.p)-1)/2)),IF(SUM(--(MOD(_xlpm.p,_xlfn.SEQUENCE(_xlpm.m,1,3,2))=0))=0,"Oui","Non"))))))} -> Non
A8: Modèle n≤7 | B8: XIII simple | C8: XIII simple ou XII terminal | G8: 3 | H8: 8 | I8: 1 | J8: {=IF($B$7<8,NA(),$B$14+I8*INDEX(_xlfn.ANCHORARRAY($B$19),H8))} -> 86385 | K8: =IFERROR(($C$14-J8)/$B$6^6,NA()) -> 209 | L8: =IFERROR(IF(K8=INT(K8),"Oui","Non"),"Non") -> Oui | M8: {=_xlfn.LET(_xlpm.p,K8,IF(OR(L8<>"Oui",_xlpm.p<2),"Non",IF(_xlpm.p=2,"Oui",IF(MOD(_xlpm.p,2)=0,"Non",_xlfn.LET(_xlpm.m,MAX(1,INT((SQRT(_xlpm.p)-1)/2)),IF(SUM(--(MOD(_xlpm.p,_xlfn.SEQUENCE(_xlpm.m,1,3,2))=0))=0,"Oui","Non"))))))} -> Non
A9: Régime | B9: Positif | C9: Positif ou Négatif | G9: 4 | H9: 8 | I9: -1 | J9: {=IF($B$7<8,NA(),$B$14+I9*INDEX(_xlfn.ANCHORARRAY($B$19),H9))} -> 73263 | K9: =IFERROR(($C$14-J9)/$B$6^6,NA()) -> 227 | L9: =IFERROR(IF(K9=INT(K9),"Oui","Non"),"Non") -> Oui | M9: {=_xlfn.LET(_xlpm.p,K9,IF(OR(L9<>"Oui",_xlpm.p<2),"Non",IF(_xlpm.p=2,"Oui",IF(MOD(_xlpm.p,2)=0,"Non",_xlfn.LET(_xlpm.m,MAX(1,INT((SQRT(_xlpm.p)-1)/2)),IF(SUM(--(MOD(_xlpm.p,_xlfn.SEQUENCE(_xlpm.m,1,3,2))=0))=0,"Oui","Non"))))))} -> Oui
A10: a₁ | B10: =B6 -> 3 | C10: Valeur initiale | G10: Candidats premiers | H10: =COUNTIF(M6:M9,"Oui") -> 1 | I10: =IF(H10=0,"Aucun candidat",IF(H10=1,"Sélection unique",H10&" candidats : critère supplémentaire requis")) -> Sélection unique
A12: SOMMES ET CONTRÔLES | G12: CONTRÔLE DU RAPPORT ET DE LA PORTÉE
A13: Mesure | B13: Suite A | C13: Suite B | D13: Écart A | E13: Écart B | G13: Contrôle | H13: Résultat
A14: Somme construite | B14: =SUM(_xlfn.ANCHORARRAY(B19)) -> 79824 | C14: =SUM(_xlfn.ANCHORARRAY(C19)) -> 238746 | G14: Rapport demandé | H14: ="1/"&B6 -> 1/3
A15: Somme fermée | B15: =_xlfn.LET(_xlpm.k,$B$6,_xlpm.n,$B$7,_xlpm.a,_xlfn.XLOOKUP(_xlpm.k,tblConstantes[k],tblConstantes[αA],""),_xlpm.o,_xlfn.XLOOKUP(_xlpm.k,tblConstantes[k],tblConstantes[offset A],""),IF(_xlpm.a="","",IF($B$9="Positif",(_xlpm.a/2)*_xlpm.k^_xlpm.n-_xlpm.o,_xlpm.a/_xlpm.k^_xlpm.n-_xlpm.o))) -> 239475 | C15: =_xlfn.LET(_xlpm.k,$B$6,_xlpm.n,$B$7,_xlpm.a,_xlfn.XLOOKUP(_xlpm.k,tblConstantes[k],tblConstantes[αB],""),_xlpm.o,_xlfn.XLOOKUP(_xlpm.k,tblConstantes[k],tblConstantes[offset B],""),IF(_xlpm.a="","",IF($B$9="Positif",(_xlpm.a/2)*_xlpm.k^_xlpm.n-_xlpm.o,_xlpm.a/_xlpm.k^_xlpm.n-_xlpm.o))) -> 717699 | D15: =IF(B15="","",B14-B15) -> -159651 | E15: =IF(C15="","",C14-C15) -> -478953 | G15: Constantes disponibles? | H15: =IF(ISNUMBER(_xlfn.XMATCH(B6,tblConstantes[k])),"Oui","Non — compléter tblConstantes") -> Oui
G16: Domaine n | H16: =IF(B7<=7,"Cas 1 à 7 : "&B8,"Cas stabilisé n≥8") -> Cas stabilisé n≥8
A17: CONSTRUCTION TERME À TERME | G17: Zêta | H17: =B6^6 -> 729
A18: Position | B18: Terme A | C18: Terme B | D18: Règle A | E18: Règle B | G18: État du moteur | H18: =IF(B7<8,"Construction active; Digamma non défini pour n<8",IF(H10=1,"Résultat unique","Essai-erreur actif; "&H10&" candidat(s) premier(s)")) -> Résultat unique
A19: {=_xlfn.SEQUENCE($B$7)} -> 1 | B19: {=_xlfn.LET(_xlpm.i,_xlfn.ANCHORARRAY(A19),_xlpm.n,$B$7,_xlpm.a,$B$10,_xlpm.r,$B$6,_xlpm.small,$B$8,IF(_xlpm.n<=7,IF(_xlpm.small="XIII simple",_xlpm.a*_xlpm.r^(_xlpm.i-1),IF(_xlpm.i=1,_xlpm.a,IF((_xlpm.n=2)*(_xlpm.i=2),_xlpm.a*(_xlpm.r-1/_xlpm.r),IF((_xlpm.n>=3)*(_xlpm.i<=_xlpm.n-2),_xlpm.a*_xlpm.r^(_xlpm.i-1),IF((_xlpm.n>=3)*(_xlpm.i=_xlpm.n-1),_xlpm.a*_xlpm.r^(_xlpm.n-3)*(_xlpm.r-1/_xlpm.r),IF((_xlpm.n>=3)*(_xlpm.i=_xlpm.n),_xlpm.a*_xlpm.r^(_xlpm.n-3)*(_xlpm.r-1/_xlpm.r)*_xlpm.r,0)))))),IF(_xlpm.i=1,_xlpm.a,IF(_xlpm.i<=_xlpm.n-2,_xlpm.a*_xlpm.r^(_xlpm.i-1),IF(_xlpm.i=_xlpm.n-1,(_xlpm.r-1/_xlpm.r)*(_xlpm.a*_xlpm.r^(_xlpm.n-3)),IF(_xlpm.i=_xlpm.n,(_xlpm.r-1/_xlpm.r)*(_xlpm.a*_xlpm.r^(_xlpm.n-2)),0))))))} -> 3 | C19: {=_xlfn.LET(_xlpm.i,_xlfn.ANCHORARRAY(A19),_xlpm.n,$B$7,_xlpm.a,$B$10,_xlpm.r,$B$6,_xlpm.small,$B$8,IF(_xlpm.n<=7,_xlfn.ANCHORARRAY(B19),IF(_xlpm.i=1,_xlpm.a,IF(_xlpm.i<=5,_xlpm.a*_xlpm.r^(_xlpm.i-1),IF(_xlpm.i=6,_xlpm.a*_xlpm.r^6,IF(_xlpm.i<=_xlpm.n-2,_xlpm.a*_xlpm.r^_xlpm.i,IF(_xlpm.i=_xlpm.n-1,(_xlpm.r-1/_xlpm.r)*(_xlpm.a*_xlpm.r^(_xlpm.n-2)),IF(_xlpm.i=_xlpm.n,(_xlpm.r-1/_xlpm.r)*(_xlpm.a*_xlpm.r^(_xlpm.n-1)),0))))))))} -> 3 | D19: {=_xlfn.LET(_xlpm.i,_xlfn.ANCHORARRAY(A19),_xlpm.n,$B$7,IF(_xlpm.n<=7,IF($B$8="XIII simple","Progression simple","XII cas terminal"),IF(_xlpm.i<=_xlpm.n-2,"Progression simple",IF(_xlpm.i=_xlpm.n-1,"Avant-dernier Savard","Dernier Savard"))))} -> Progression simple | E19: {=_xlfn.LET(_xlpm.i,_xlfn.ANCHORARRAY(A19),_xlpm.n,$B$7,IF(_xlpm.n<=7,"Identique à A",IF(_xlpm.i<=5,"Progression simple",IF(_xlpm.i=6,"Saut Zêta",IF(_xlpm.i<=_xlpm.n-2,"Progression décalée",IF(_xlpm.i=_xlpm.n-1,"Avant-dernier Savard","Dernier Savard"))))))} -> Progression simple
A20: 2 | B20: 9 | C20: 9 | D20: Progression simple | E20: Progression simple | G20: LIMITES FORMELLES
A21: 3 | B21: 27 | C21: 27 | D21: Progression simple | E21: Progression simple | G21: Le moteur construit A et B pour tout k≥2 et n≥1. Les sommes fermées ne sont calculables que si αA, αB et les offsets du rapport sont connus. Les quatre Digamma sont testés sans supposer qu’un résultat premier est nécessairement unique.
A22: 4 | B22: 81 | C22: 81 | D22: Progression simple | E22: Progression simple
A23: 5 | B23: 243 | C23: 243 | D23: Progression simple | E23: Progression simple
A24: 6 | B24: 729 | C24: 2187 | D24: Progression simple | E24: Saut Zêta
A25: 7 | B25: 2187 | C25: 6561 | D25: Progression simple | E25: Progression décalée
A26: 8 | B26: 6561 | C26: 19683 | D26: Progression simple | E26: Progression décalée
A27: 9 | B27: 17496 | C27: 52488 | D27: Avant-dernier Savard | E27: Avant-dernier Savard
A28: 10 | B28: 52488 | C28: 157464 | D28: Dernier Savard | E28: Dernier Savard

Sheet Modèle Formel
A1: Modèle formel universel — rapport 1/k
A2: Aucune valeur numérique par défaut : saisissez k et n, puis le modèle substitue ces valeurs aux formes universelles A(n,i), B(n,i) et teste les quatre Digamma.
A4: VARIABLES À SUBSTITUER | D4: SORTIES GÉNÉRALES
A5: Variable | B5: Valeur | C5: Définition | D5: Mesure | E5: Résultat
A6: k | B6: 12 | C6: Dénominateur du rapport 1/k | D6: Somme A(n) | E6: =IF(OR($B$6="",$B$7=""),"",SUM(_xlfn.ANCHORARRAY(C29))) -> 1.6691751e+16
A7: n | B7: 15 | C7: Nombre de termes | D7: Somme B(n) | E7: =IF(OR($B$6="",$B$7=""),"",SUM(_xlfn.ANCHORARRAY(E29))) -> 2.0030101e+17
A8: 1/k | B8: =IF(B6="","","1/"&B6) | C8: Rapport demandé | D8: Zêta | E8: =IF($B$6="","",$B$6^6) -> 2985984
A9: a₁ | B9: =IF(B6="","",B6) -> 12 | C9: a₁ := k | D9: Premiers candidats | E9: =IF(OR($B$6="",$B$7<8),"",COUNTIF(G15:G18,"Oui")) -> 1
A10: r | B10: =IF(B6="","",B6) -> 12 | C10: r := k | D10: État | E10: =IF(OR($B$6="",$B$7=""),"En attente de k et n",IF($B$7<8,"Suites construites; Digamma défini seulement pour n≥8",IF(E9=0,"Aucun candidat premier",IF(E9=1,"Un candidat premier",E9&" candidats premiers")))) -> Un candidat premier
A11: Modèle n≤7 | B11: XIII simple | C11: XIII simple ou XII terminal | D11: Certitude | E11: =IF(OR($B$6="",$B$7=""),"",IF($B$7<8,"Reconstruction P non applicable",IF(E9=1,"P déterminé de façon unique dans les quatre essais","P non unique avec les règles actuelles"))) -> P déterminé de façon unique dans les quatre essais
A13: QUATRE POSSIBILITÉS DU DIGAMMA
A14: Option | B14: Position | C14: Signe | D14: Digamma calculé | E14: P reconstruit | F14: Entier? | G14: Premier?
A15: 1 | B15: 7 | C15: 1 | D15: {=IF(OR($B$6="",$B$7<8),"",$E$6+C15*INDEX(_xlfn.ANCHORARRAY(C29),B15))} -> 1.6691751e+16 | E15: =IF(D15="","",($E$7-D15)/$E$8) -> 61490368499 | F15: =IF(E15="","",IF(E15=INT(E15),"Oui","Non")) -> Oui | G15: {=IF(E15="","",IFERROR(_xlfn.LET(_xlpm.p,E15,IF(OR(F15<>"Oui",_xlpm.p<2),"Non",IF(_xlpm.p=2,"Oui",IF(MOD(_xlpm.p,2)=0,"Non",_xlfn.LET(_xlpm.m,MAX(1,INT((SQRT(_xlpm.p)-1)/2)),IF(SUM(--(MOD(_xlpm.p,_xlfn.SEQUENCE(_xlpm.m,1,3,2))=0))=0,"Oui","Non")))))),"Non"))} -> Non
A16: 2 | B16: 7 | C16: -1 | D16: {=IF(OR($B$6="",$B$7<8),"",$E$6+C16*INDEX(_xlfn.ANCHORARRAY(C29),B16))} -> 1.6691751e+16 | E16: =IF(D16="","",($E$7-D16)/$E$8) -> 61490368523 | F16: =IF(E16="","",IF(E16=INT(E16),"Oui","Non")) -> Oui | G16: {=IF(E16="","",IFERROR(_xlfn.LET(_xlpm.p,E16,IF(OR(F16<>"Oui",_xlpm.p<2),"Non",IF(_xlpm.p=2,"Oui",IF(MOD(_xlpm.p,2)=0,"Non",_xlfn.LET(_xlpm.m,MAX(1,INT((SQRT(_xlpm.p)-1)/2)),IF(SUM(--(MOD(_xlpm.p,_xlfn.SEQUENCE(_xlpm.m,1,3,2))=0))=0,"Oui","Non")))))),"Non"))} -> Oui
A17: 3 | B17: 8 | C17: 1 | D17: {=IF(OR($B$6="",$B$7<8),"",$E$6+C17*INDEX(_xlfn.ANCHORARRAY(C29),B17))} -> 1.6691751e+16 | E17: =IF(D17="","",($E$7-D17)/$E$8) -> 61490368367 | F17: =IF(E17="","",IF(E17=INT(E17),"Oui","Non")) -> Oui | G17: {=IF(E17="","",IFERROR(_xlfn.LET(_xlpm.p,E17,IF(OR(F17<>"Oui",_xlpm.p<2),"Non",IF(_xlpm.p=2,"Oui",IF(MOD(_xlpm.p,2)=0,"Non",_xlfn.LET(_xlpm.m,MAX(1,INT((SQRT(_xlpm.p)-1)/2)),IF(SUM(--(MOD(_xlpm.p,_xlfn.SEQUENCE(_xlpm.m,1,3,2))=0))=0,"Oui","Non")))))),"Non"))} -> Non
A18: 4 | B18: 8 | C18: -1 | D18: {=IF(OR($B$6="",$B$7<8),"",$E$6+C18*INDEX(_xlfn.ANCHORARRAY(C29),B18))} -> 1.669175e+16 | E18: =IF(D18="","",($E$7-D18)/$E$8) -> 61490368655 | F18: =IF(E18="","",IF(E18=INT(E18),"Oui","Non")) -> Oui | G18: {=IF(E18="","",IFERROR(_xlfn.LET(_xlpm.p,E18,IF(OR(F18<>"Oui",_xlpm.p<2),"Non",IF(_xlpm.p=2,"Oui",IF(MOD(_xlpm.p,2)=0,"Non",_xlfn.LET(_xlpm.m,MAX(1,INT((SQRT(_xlpm.p)-1)/2)),IF(SUM(--(MOD(_xlpm.p,_xlfn.SEQUENCE(_xlpm.m,1,3,2))=0))=0,"Oui","Non")))))),"Non"))} -> Non
A20: DÉFINITIONS FORMELLES APPLIQUÉES
A21: n ≤ 7, modèle XIII : A(n,i)=a₁·r^(i−1) et B(n,i)=A(n,i).
A22: n ≤ 7, modèle XII : cas terminaux avec le facteur (r−1/r); B(n,i)=A(n,i).
A23: n ≥ 8 : A suit la progression jusqu’à n−2, puis les deux termes terminaux Savard.
A24: n ≥ 8 : B insère a₁·r^6 à i=6, décale la progression et applique ses termes terminaux.
A25: Reconstruction : P=[Somme B(n)−(Somme A(n)±A(n,7 ou 8))]/k^6.
A27: CONSTRUCTION TERME À TERME
A28: Position i | B28: Forme A(n,i) | C28: Valeur substituée A | D28: Forme B(n,i) | E28: Valeur substituée B
A29: {=IF(OR($B$6="",$B$7=""),"",_xlfn.SEQUENCE($B$7))} -> 1 | B29: {=IF(_xlfn.ANCHORARRAY(A29)="","",_xlfn.LET(_xlpm.i,_xlfn.ANCHORARRAY(A29),_xlpm.n,$B$7,IF(_xlpm.n<=7,IF($B$11="XIII simple","a₁·r^(i−1)",IF(_xlpm.i=1,"a₁",IF((_xlpm.n=2)*(_xlpm.i=2),"a₁·(r−1/r)",IF(_xlpm.i<=_xlpm.n-2,"a₁·r^(i−1)",IF(_xlpm.i=_xlpm.n-1,"a₁·r^(n−3)·(r−1/r)","a₁·r^(n−3)·(r−1/r)·r"))))),IF(_xlpm.i=1,"a₁",IF(_xlpm.i<=_xlpm.n-2,"a₁·r^(i−1)",IF(_xlpm.i=_xlpm.n-1,"(r−1/r)·a₁·r^(n−3)","(r−1/r)·a₁·r^(n−2)"))))))} -> a₁ | C29: {=IF(_xlfn.ANCHORARRAY(A29)="","",_xlfn.LET(_xlpm.i,_xlfn.ANCHORARRAY(A29),_xlpm.n,$B$7,_xlpm.a,$B$9,_xlpm.r,$B$10,IF(_xlpm.n<=7,IF($B$11="XIII simple",_xlpm.a*_xlpm.r^(_xlpm.i-1),IF(_xlpm.i=1,_xlpm.a,IF((_xlpm.n=2)*(_xlpm.i=2),_xlpm.a*(_xlpm.r-1/_xlpm.r),IF((_xlpm.n>=3)*(_xlpm.i<=_xlpm.n-2),_xlpm.a*_xlpm.r^(_xlpm.i-1),IF((_xlpm.n>=3)*(_xlpm.i=_xlpm.n-1),_xlpm.a*_xlpm.r^(_xlpm.n-3)*(_xlpm.r-1/_xlpm.r),IF((_xlpm.n>=3)*(_xlpm.i=_xlpm.n),_xlpm.a*_xlpm.r^(_xlpm.n-3)*(_xlpm.r-1/_xlpm.r)*_xlpm.r,0)))))),IF(_xlpm.i=1,_xlpm.a,IF(_xlpm.i<=_xlpm.n-2,_xlpm.a*_xlpm.r^(_xlpm.i-1),IF(_xlpm.i=_xlpm.n-1,(_xlpm.r-1/_xlpm.r)*(_xlpm.a*_xlpm.r^(_xlpm.n-3)),IF(_xlpm.i=_xlpm.n,(_xlpm.r-1/_xlpm.r)*(_xlpm.a*_xlpm.r^(_xlpm.n-2)),0)))))))} -> 12 | D29: {=IF(_xlfn.ANCHORARRAY(A29)="","",_xlfn.LET(_xlpm.i,_xlfn.ANCHORARRAY(A29),_xlpm.n,$B$7,IF(_xlpm.n<=7,"A(n,i)",IF(_xlpm.i=1,"a₁",IF(_xlpm.i<=5,"a₁·r^(i−1)",IF(_xlpm.i=6,"a₁·r^6 [Zêta]",IF(_xlpm.i<=_xlpm.n-2,"a₁·r^i",IF(_xlpm.i=_xlpm.n-1,"(r−1/r)·a₁·r^(n−2)","(r−1/r)·a₁·r^(n−1)"))))))))} -> a₁ | E29: {=IF(_xlfn.ANCHORARRAY(A29)="","",_xlfn.LET(_xlpm.i,_xlfn.ANCHORARRAY(A29),_xlpm.n,$B$7,_xlpm.a,$B$9,_xlpm.r,$B$10,IF(_xlpm.n<=7,_xlfn.ANCHORARRAY(C29),IF(_xlpm.i=1,_xlpm.a,IF(_xlpm.i<=5,_xlpm.a*_xlpm.r^(_xlpm.i-1),IF(_xlpm.i=6,_xlpm.a*_xlpm.r^6,IF(_xlpm.i<=_xlpm.n-2,_xlpm.a*_xlpm.r^_xlpm.i,IF(_xlpm.i=_xlpm.n-1,(_xlpm.r-1/_xlpm.r)*(_xlpm.a*_xlpm.r^(_xlpm.n-2)),IF(_xlpm.i=_xlpm.n,(_xlpm.r-1/_xlpm.r)*(_xlpm.a*_xlpm.r^(_xlpm.n-1)),0)))))))))} -> 12
A30: 2 | B30: a₁·r^(i−1) | C30: 144 | D30: a₁·r^(i−1) | E30: 144
A31: 3 | B31: a₁·r^(i−1) | C31: 1728 | D31: a₁·r^(i−1) | E31: 1728
A32: 4 | B32: a₁·r^(i−1) | C32: 20736 | D32: a₁·r^(i−1) | E32: 20736
A33: 5 | B33: a₁·r^(i−1) | C33: 248832 | D33: a₁·r^(i−1) | E33: 248832
A34: 6 | B34: a₁·r^(i−1) | C34: 2985984 | D34: a₁·r^6 [Zêta] | E34: 35831808
A35: 7 | B35: a₁·r^(i−1) | C35: 35831808 | D35: a₁·r^i | E35: 429981696
A36: 8 | B36: a₁·r^(i−1) | C36: 429981696 | D36: a₁·r^i | E36: 5159780352
A37: 9 | B37: a₁·r^(i−1) | C37: 5159780352 | D37: a₁·r^i | E37: 61917364224
A38: 10 | B38: a₁·r^(i−1) | C38: 61917364224 | D38: a₁·r^i | E38: 743008370688
A39: 11 | B39: a₁·r^(i−1) | C39: 743008370688 | D39: a₁·r^i | E39: 8916100448256
A40: 12 | B40: a₁·r^(i−1) | C40: 8916100448256 | D40: a₁·r^i | E40: 106993205379072
A41: 13 | B41: a₁·r^(i−1) | C41: 106993205379072 | D41: a₁·r^i | E41: 1.2839185e+15
... A43: 15 | B43: (r−1/r)·a₁·r^(n−2) | C43: 1.5300028e+16 | D43: (r−1/r)·a₁·r^(n−1) | E43: 1.8360034e+17
A45: MODE D’EMPLOI ET PORTÉE
A46: 1. Saisir k et n dans les cellules jaunes. 2. Choisir le modèle pour n≤7. 3. Lire les suites et les quatre candidats. Le modèle affirme un P unique seulement lorsqu’une seule option est entière et première. Il ne constitue pas une preuve que chaque rapport et chaque n produisent exactement un premier.

Sheet Démonstration Formelle
A1: Démonstration formelle universelle — tout rapport 1/k
A2: Même démonstration que Tests Digamma, lignes 21 à 57, sans substitution numérique : k demeure une variable entière positive représentant le dénominateur de 1/k.
A4: SUITES A — 10 ET 9 TERMES
A5: Position | B5: Terme A₁₀ | C5: Expression | D5: Règle | F5: Position | G5: Terme A₉ | H5: Expression | I5: Règle
A6: 1 | B6: k^1 | C6: k^1 | D6: progression | F6: 1 | G6: k^1 | H6: k^1 | I6: progression
A7: 2 | B7: k^2 | C7: k^2 | D7: progression | F7: 2 | G7: k^2 | H7: k^2 | I7: progression
A8: 3 | B8: k^3 | C8: k^3 | D8: progression | F8: 3 | G8: k^3 | H8: k^3 | I8: progression
A9: 4 | B9: k^4 | C9: k^4 | D9: progression | F9: 4 | G9: k^4 | H9: k^4 | I9: progression
A10: 5 | B10: k^5 | C10: k^5 | D10: progression | F10: 5 | G10: k^5 | H10: k^5 | I10: progression
A11: 6 | B11: k^6 | C11: k^6 | D11: progression | F11: 6 | G11: k^6 | H11: k^6 | I11: progression
A12: 7 | B12: k^7 | C12: k^7 | D12: progression | F12: 7 | G12: k^7 | H12: k^7 | I12: progression
A13: 8 | B13: k^8 | C13: k^8 | D13: progression | F13: 8 | G13: k^8 − k^6 | H13: k^8 − k^6 | I13: avant-dernier Savard
A14: 9 | B14: k^9 − k^7 | C14: k^9 − k^7 | D14: avant-dernier Savard | F14: 9 | G14: k^9 − k^7 | H14: k^9 − k^7 | I14: dernier Savard
A15: 10 | B15: k^10 − k^8 | C15: k^10 − k^8 | D15: dernier Savard | F15: Somme | G15: =_xlfn.TEXTJOIN(" + ",TRUE,G6:G14) -> k^1 + k^2 + k^3 + k^4 + k^5 + k^6 + k^7 + k^8 − k^6 + k^9 − k^7 | H15: =_xlfn.TEXTJOIN(" + ",TRUE,H6:H14) -> k^1 + k^2 + k^3 + k^4 + k^5 + k^6 + k^7 + k^8 − k^6 + k^9 − k^7
A16: Somme | B16: =_xlfn.TEXTJOIN(" + ",TRUE,B6:B15) -> k^1 + k^2 + k^3 + k^4 + k^5 + k^6 + k^7 + k^8 + k^9 − k^7 + k^10 − k^8 | C16: =_xlfn.TEXTJOIN(" + ",TRUE,C6:C15) -> k^1 + k^2 + k^3 + k^4 + k^5 + k^6 + k^7 + k^8 + k^9 − k^7 + k^10 − k^8
A18: SUITES B — 10 ET 9 TERMES AVEC SAUT ZÊTA
A19: Position | B19: Terme B₁₀ | C19: Expression | D19: Règle | F19: Position | G19: Terme B₉ | H19: Expression | I19: Règle
A20: 1 | B20: k^1 | C20: k^1 | D20: progression | F20: 1 | G20: k^1 | H20: k^1 | I20: progression
A21: 2 | B21: k^2 | C21: k^2 | D21: progression | F21: 2 | G21: k^2 | H21: k^2 | I21: progression
A22: 3 | B22: k^3 | C22: k^3 | D22: progression | F22: 3 | G22: k^3 | H22: k^3 | I22: progression
A23: 4 | B23: k^4 | C23: k^4 | D23: progression | F23: 4 | G23: k^4 | H23: k^4 | I23: progression
A24: 5 | B24: k^5 | C24: k^5 | D24: progression | F24: 5 | G24: k^5 | H24: k^5 | I24: progression
A25: 6 | B25: k^7 | C25: k^7 | D25: saut Zêta | F25: 6 | G25: k^7 | H25: k^7 | I25: saut Zêta
A26: 7 | B26: k^8 | C26: k^8 | D26: progression décalée | F26: 7 | G26: k^8 | H26: k^8 | I26: progression décalée
A27: 8 | B27: k^9 | C27: k^9 | D27: progression décalée | F27: 8 | G27: k^9 − k^7 | H27: k^9 − k^7 | I27: avant-dernier Savard
A28: 9 | B28: k^10 − k^8 | C28: k^10 − k^8 | D28: avant-dernier Savard | F28: 9 | G28: k^10 − k^8 | H28: k^10 − k^8 | I28: dernier Savard
A29: 10 | B29: k^11 − k^9 | C29: k^11 − k^9 | D29: dernier Savard | F29: Somme | G29: =_xlfn.TEXTJOIN(" + ",TRUE,G20:G28) -> k^1 + k^2 + k^3 + k^4 + k^5 + k^7 + k^8 + k^9 − k^7 + k^10 − k^8 | H29: =_xlfn.TEXTJOIN(" + ",TRUE,H20:H28) -> k^1 + k^2 + k^3 + k^4 + k^5 + k^7 + k^8 + k^9 − k^7 + k^10 − k^8
A30: Somme | B30: =_xlfn.TEXTJOIN(" + ",TRUE,B20:B29) -> k^1 + k^2 + k^3 + k^4 + k^5 + k^7 + k^8 + k^9 + k^10 − k^8 + k^11 − k^9 | C30: =_xlfn.TEXTJOIN(" + ",TRUE,C20:C29) -> k^1 + k^2 + k^3 + k^4 + k^5 + k^7 + k^8 + k^9 + k^10 − k^8 + k^11 − k^9
A32: QUATRE POSSIBILITÉS DU DIGAMMA
A33: Option | B33: Position | C33: Terme | D33: Opération | E33: Forme concise | F33: Développement universel | G33: Statut
A34: 1 | B34: 7 | C34: k^7 | D34: + | E34: ="Somme_A10 "&D34&" "&C34 -> Somme_A10 + k^7 | F34: ="("&$C$16&") "&D34&" "&C34 -> (k^1 + k^2 + k^3 + k^4 + k^5 + k^6 + k^7 + k^8 + k^9 − k^7 + k^10 − k^8) + k^7 | G34: À tester
A35: 2 | B35: 7 | C35: k^7 | D35: − | E35: ="Somme_A10 "&D35&" "&C35 -> Somme_A10 − k^7 | F35: ="("&$C$16&") "&D35&" "&C35 -> (k^1 + k^2 + k^3 + k^4 + k^5 + k^6 + k^7 + k^8 + k^9 − k^7 + k^10 − k^8) − k^7 | G35: À tester
A36: 3 | B36: 8 | C36: k^8 | D36: + | E36: ="Somme_A10 "&D36&" "&C36 -> Somme_A10 + k^8 | F36: ="("&$C$16&") "&D36&" "&C36 -> (k^1 + k^2 + k^3 + k^4 + k^5 + k^6 + k^7 + k^8 + k^9 − k^7 + k^10 − k^8) + k^8 | G36: À tester
A37: 4 | B37: 8 | C37: k^8 | D37: − | E37: ="Somme_A10 "&D37&" "&C37 -> Somme_A10 − k^8 | F37: ="("&$C$16&") "&D37&" "&C37 -> (k^1 + k^2 + k^3 + k^4 + k^5 + k^6 + k^7 + k^8 + k^9 − k^7 + k^10 − k^8) − k^8 | G37: À tester
A39: RECONSTRUCTION FORMELLE DES QUATRE CANDIDATS P
A40: Option | B40: Digamma calculé | C40: Somme B₁₀ | D40: Zêta | E40: Équation formelle | F40: Candidat P | G40: Condition entière | H40: Condition première | I40: Décision
A41: 1 | B41: =E34 -> Somme_A10 + k^7 | C41: ="Somme_B10" -> Somme_B10 | D41: k^6 | E41: ="P"&A41&" = [Somme_B10 − ("&B41&")] / k^6" -> P1 = [Somme_B10 − (Somme_A10 + k^7)] / k^6 | F41: ="[Somme_B10 − ("&B41&")] / k^6" -> [Somme_B10 − (Somme_A10 + k^7)] / k^6 | G41: P ∈ ℤ | H41: P premier | I41: Essai-erreur
A42: 2 | B42: =E35 -> Somme_A10 − k^7 | C42: ="Somme_B10" -> Somme_B10 | D42: k^6 | E42: ="P"&A42&" = [Somme_B10 − ("&B42&")] / k^6" -> P2 = [Somme_B10 − (Somme_A10 − k^7)] / k^6 | F42: ="[Somme_B10 − ("&B42&")] / k^6" -> [Somme_B10 − (Somme_A10 − k^7)] / k^6 | G42: P ∈ ℤ | H42: P premier | I42: Essai-erreur
A43: 3 | B43: =E36 -> Somme_A10 + k^8 | C43: ="Somme_B10" -> Somme_B10 | D43: k^6 | E43: ="P"&A43&" = [Somme_B10 − ("&B43&")] / k^6" -> P3 = [Somme_B10 − (Somme_A10 + k^8)] / k^6 | F43: ="[Somme_B10 − ("&B43&")] / k^6" -> [Somme_B10 − (Somme_A10 + k^8)] / k^6 | G43: P ∈ ℤ | H43: P premier | I43: Essai-erreur
A44: 4 | B44: =E37 -> Somme_A10 − k^8 | C44: ="Somme_B10" -> Somme_B10 | D44: k^6 | E44: ="P"&A44&" = [Somme_B10 − ("&B44&")] / k^6" -> P4 = [Somme_B10 − (Somme_A10 − k^8)] / k^6 | F44: ="[Somme_B10 − ("&B44&")] / k^6" -> [Somme_B10 − (Somme_A10 − k^8)] / k^6 | G44: P ∈ ℤ | H44: P premier | I44: Essai-erreur
...

Sheet Convolution
A1: Table de convolution formelle
A2: Chaque terme vaut c₁·k^e₁ + c₂·k^e₂. Cette représentation encode les additions et soustractions sans figer k.
A4: TERMES DES SUITES
A5: Rapport | B5: Suite | C5: Ordre | D5: Coeff 1 | E5: Exposant 1 | F5: Coeff 2 | G5: Exposant 2 | H5: Valeur | I5: Expression formelle
A6: 1/3 | B6: A | C6: 1 | D6: 1 | E6: 1 | F6: 0 | G6: 0 | H6: =tblConvolution[[#This Row],[Coeff 1]]*_xlfn.XLOOKUP(tblConvolution[[#This Row],[Rapport]],tblRegles[Rapport],tblRegles[k])^tblConvolution[[#This Row],[Exposant 1]]+tblConvolution[[#This Row],[Coeff 2]]*_xlfn.XLOOKUP(tblConvolution[[#This Row],[Rapport]],tblRegles[Rapport],tblRegles[k])^tblConvolution[[#This Row],[Exposant 2]] -> 3 | I6: k^1
A7: 1/3 | B7: A | C7: 2 | D7: 1 | E7: 2 | F7: 0 | G7: 0 | H7: =tblConvolution[[#This Row],[Coeff 1]]*_xlfn.XLOOKUP(tblConvolution[[#This Row],[Rapport]],tblRegles[Rapport],tblRegles[k])^tblConvolution[[#This Row],[Exposant 1]]+tblConvolution[[#This Row],[Coeff 2]]*_xlfn.XLOOKUP(tblConvolution[[#This Row],[Rapport]],tblRegles[Rapport],tblRegles[k])^tblConvolution[[#This Row],[Exposant 2]] -> 9 | I7: k^2
A8: 1/3 | B8: A | C8: 3 | D8: 1 | E8: 3 | F8: 0 | G8: 0 | H8: =tblConvolution[[#This Row],[Coeff 1]]*_xlfn.XLOOKUP(tblConvolution[[#This Row],[Rapport]],tblRegles[Rapport],tblRegles[k])^tblConvolution[[#This Row],[Exposant 1]]+tblConvolution[[#This Row],[Coeff 2]]*_xlfn.XLOOKUP(tblConvolution[[#This Row],[Rapport]],tblRegles[Rapport],tblRegles[k])^tblConvolution[[#This Row],[Exposant 2]] -> 27 | I8: k^3
A9: 1/3 | B9: A | C9: 4 | D9: 1 | E9: 4 | F9: 0 | G9: 0 | H9: =tblConvolution[[#This Row],[Coeff 1]]*_xlfn.XLOOKUP(tblConvolution[[#This Row],[Rapport]],tblRegles[Rapport],tblRegles[k])^tblConvolution[[#This Row],[Exposant 1]]+tblConvolution[[#This Row],[Coeff 2]]*_xlfn.XLOOKUP(tblConvolution[[#This Row],[Rapport]],tblRegles[Rapport],tblRegles[k])^tblConvolution[[#This Row],[Exposant 2]] -> 81 | I9: k^4
A10: 1/3 | B10: A | C10: 5 | D10: 1 | E10: 5 | F10: 0 | G10: 0 | H10: =tblConvolution[[#This Row],[Coeff 1]]*_xlfn.XLOOKUP(tblConvolution[[#This Row],[Rapport]],tblRegles[Rapport],tblRegles[k])^tblConvolution[[#This Row],[Exposant 1]]+tblConvolution[[#This Row],[Coeff 2]]*_xlfn.XLOOKUP(tblConvolution[[#This Row],[Rapport]],tblRegles[Rapport],tblRegles[k])^tblConvolution[[#This Row],[Exposant 2]] -> 243 | I10: k^5
A11: 1/3 | B11: A | C11: 6 | D11: 1 | E11: 6 | F11: 0 | G11: 0 | H11: =tblConvolution[[#This Row],[Coeff 1]]*_xlfn.XLOOKUP(tblConvolution[[#This Row],[Rapport]],tblRegles[Rapport],tblRegles[k])^tblConvolution[[#This Row],[Exposant 1]]+tblConvolution[[#This Row],[Coeff 2]]*_xlfn.XLOOKUP(tblConvolution[[#This Row],[Rapport]],tblRegles[Rapport],tblRegles[k])^tblConvolution[[#This Row],[Exposant 2]] -> 729 | I11: k^6
A12: 1/3 | B12: A | C12: 7 | D12: 1 | E12: 7 | F12: 0 | G12: 0 | H12: =tblConvolution[[#This Row],[Coeff 1]]*_xlfn.XLOOKUP(tblConvolution[[#This Row],[Rapport]],tblRegles[Rapport],tblRegles[k])^tblConvolution[[#This Row],[Exposant 1]]+tblConvolution[[#This Row],[Coeff 2]]*_xlfn.XLOOKUP(tblConvolution[[#This Row],[Rapport]],tblRegles[Rapport],tblRegles[k])^tblConvolution[[#This Row],[Exposant 2]] -> 2187 | I12: k^7
A13: 1/3 | B13: A | C13: 8 | D13: 1 | E13: 8 | F13: 0 | G13: 0 | H13: =tblConvolution[[#This Row],[Coeff 1]]*_xlfn.XLOOKUP(tblConvolution[[#This Row],[Rapport]],tblRegles[Rapport],tblRegles[k])^tblConvolution[[#This Row],[Exposant 1]]+tblConvolution[[#This Row],[Coeff 2]]*_xlfn.XLOOKUP(tblConvolution[[#This Row],[Rapport]],tblRegles[Rapport],tblRegles[k])^tblConvolution[[#This Row],[Exposant 2]] -> 6561 | I13: k^8
A14: 1/3 | B14: A | C14: 9 | D14: 1 | E14: 9 | F14: -1 | G14: 7 | H14: =tblConvolution[[#This Row],[Coeff 1]]*_xlfn.XLOOKUP(tblConvolution[[#This Row],[Rapport]],tblRegles[Rapport],tblRegles[k])^tblConvolution[[#This Row],[Exposant 1]]+tblConvolution[[#This Row],[Coeff 2]]*_xlfn.XLOOKUP(tblConvolution[[#This Row],[Rapport]],tblRegles[Rapport],tblRegles[k])^tblConvolution[[#This Row],[Exposant 2]] -> 17496 | I14: k^9 - k^7
A15: 1/3 | B15: A | C15: 10 | D15: 1 | E15: 10 | F15: -1 | G15: 8 | H15: =tblConvolution[[#This Row],[Coeff 1]]*_xlfn.XLOOKUP(tblConvolution[[#This Row],[Rapport]],tblRegles[Rapport],tblRegles[k])^tblConvolution[[#This Row],[Exposant 1]]+tblConvolution[[#This Row],[Coeff 2]]*_xlfn.XLOOKUP(tblConvolution[[#This Row],[Rapport]],tblRegles[Rapport],tblRegles[k])^tblConvolution[[#This Row],[Exposant 2]] -> 52488 | I15: k^10 - k^8
A16: 1/3 | B16: B | C16: 1 | D16: 1 | E16: 1 | F16: 0 | G16: 0 | H16: =tblConvolution[[#This Row],[Coeff 1]]*_xlfn.XLOOKUP(tblConvolution[[#This Row],[Rapport]],tblRegles[Rapport],tblRegles[k])^tblConvolution[[#This Row],[Exposant 1]]+tblConvolution[[#This Row],[Coeff 2]]*_xlfn.XLOOKUP(tblConvolution[[#This Row],[Rapport]],tblRegles[Rapport],tblRegles[k])^tblConvolution[[#This Row],[Exposant 2]] -> 3 | I16: k^1
A17: 1/3 | B17: B | C17: 2 | D17: 1 | E17: 2 | F17: 0 | G17: 0 | H17: =tblConvolution[[#This Row],[Coeff 1]]*_xlfn.XLOOKUP(tblConvolution[[#This Row],[Rapport]],tblRegles[Rapport],tblRegles[k])^tblConvolution[[#This Row],[Exposant 1]]+tblConvolution[[#This Row],[Coeff 2]]*_xlfn.XLOOKUP(tblConvolution[[#This Row],[Rapport]],tblRegles[Rapport],tblRegles[k])^tblConvolution[[#This Row],[Exposant 2]] -> 9 | I17: k^2
... A25: 1/3 | B25: B | C25: 10 | D25: 1 | E25: 11 | F25: -1 | G25: 9 | H25: =tblConvolution[[#This Row],[Coeff 1]]*_xlfn.XLOOKUP(tblConvolution[[#This Row],[Rapport]],tblRegles[Rapport],tblRegles[k])^tblConvolution[[#This Row],[Exposant 1]]+tblConvolution[[#This Row],[Coeff 2]]*_xlfn.XLOOKUP(tblConvolution[[#This Row],[Rapport]],tblRegles[Rapport],tblRegles[k])^tblConvolution[[#This Row],[Exposant 2]] -> 157464 | I25: k^11 - k^9

Sheet Tests Digamma
A1: Tests des quatre Digamma
A2: Le candidat est A ajustée = Somme A + signe·k^position; puis P = (Somme B − A ajustée)/k^exp_reconstruction.
A4: CANDIDATS POUR 1/3
A5: Rapport | B5: k | C5: Position | D5: Signe | E5: Somme A | F5: Somme B | G5: Rang
A6: 1/3 | B6: 3 | C6: 7 | D6: -1 | E6: =SUMIFS(tblConvolution[Valeur],tblConvolution[Rapport],A6,tblConvolution[Suite],"A") -> 79824 | F6: =SUMIFS(tblConvolution[Valeur],tblConvolution[Rapport],A6,tblConvolution[Suite],"B") -> 238746 | G6: {=_xlfn.LET(_xlpm.p,(F6-(E6+D6*B6^C6))/B6^_xlfn.XLOOKUP(A6,tblRegles[Rapport],tblRegles[Exp reconstruction]),IF(OR(_xlpm.p<>INT(_xlpm.p),_xlpm.p<2),"",_xlfn.LET(_xlpm.q,_xlfn.SEQUENCE(INT(_xlpm.p)),_xlpm.d,TRANSPOSE(_xlfn.SEQUENCE(INT(_xlpm.p))),_xlpm.cnt,MMULT(--(MOD(_xlpm.q,_xlpm.d)=0),_xlfn.SEQUENCE(INT(_xlpm.p),,1,0)),IF(SUM(--(MOD(_xlpm.p,_xlfn.SEQUENCE(INT(_xlpm.p)))=0))=2,SUM(--(_xlpm.cnt=2)),""))))}
A7: 1/3 | B7: 3 | C7: 7 | D7: 1 | E7: =SUMIFS(tblConvolution[Valeur],tblConvolution[Rapport],A7,tblConvolution[Suite],"A") -> 79824 | F7: =SUMIFS(tblConvolution[Valeur],tblConvolution[Rapport],A7,tblConvolution[Suite],"B") -> 238746 | G7: {=_xlfn.LET(_xlpm.p,(F7-(E7+D7*B7^C7))/B7^_xlfn.XLOOKUP(A7,tblRegles[Rapport],tblRegles[Exp reconstruction]),IF(OR(_xlpm.p<>INT(_xlpm.p),_xlpm.p<2),"",_xlfn.LET(_xlpm.q,_xlfn.SEQUENCE(INT(_xlpm.p)),_xlpm.d,TRANSPOSE(_xlfn.SEQUENCE(INT(_xlpm.p))),_xlpm.cnt,MMULT(--(MOD(_xlpm.q,_xlpm.d)=0),_xlfn.SEQUENCE(INT(_xlpm.p),,1,0)),IF(SUM(--(MOD(_xlpm.p,_xlfn.SEQUENCE(INT(_xlpm.p)))=0))=2,SUM(--(_xlpm.cnt=2)),""))))}
A8: 1/3 | B8: 3 | C8: 8 | D8: -1 | E8: =SUMIFS(tblConvolution[Valeur],tblConvolution[Rapport],A8,tblConvolution[Suite],"A") -> 79824 | F8: =SUMIFS(tblConvolution[Valeur],tblConvolution[Rapport],A8,tblConvolution[Suite],"B") -> 238746 | G8: {=_xlfn.LET(_xlpm.p,(F8-(E8+D8*B8^C8))/B8^_xlfn.XLOOKUP(A8,tblRegles[Rapport],tblRegles[Exp reconstruction]),IF(OR(_xlpm.p<>INT(_xlpm.p),_xlpm.p<2),"",_xlfn.LET(_xlpm.q,_xlfn.SEQUENCE(INT(_xlpm.p)),_xlpm.d,TRANSPOSE(_xlfn.SEQUENCE(INT(_xlpm.p))),_xlpm.cnt,MMULT(--(MOD(_xlpm.q,_xlpm.d)=0),_xlfn.SEQUENCE(INT(_xlpm.p),,1,0)),IF(SUM(--(MOD(_xlpm.p,_xlfn.SEQUENCE(INT(_xlpm.p)))=0))=2,SUM(--(_xlpm.cnt=2)),""))))} -> 49
A9: 1/3 | B9: 3 | C9: 8 | D9: 1 | E9: =SUMIFS(tblConvolution[Valeur],tblConvolution[Rapport],A9,tblConvolution[Suite],"A") -> 79824 | F9: =SUMIFS(tblConvolution[Valeur],tblConvolution[Rapport],A9,tblConvolution[Suite],"B") -> 238746 | G9: {=_xlfn.LET(_xlpm.p,(F9-(E9+D9*B9^C9))/B9^_xlfn.XLOOKUP(A9,tblRegles[Rapport],tblRegles[Exp reconstruction]),IF(OR(_xlpm.p<>INT(_xlpm.p),_xlpm.p<2),"",_xlfn.LET(_xlpm.q,_xlfn.SEQUENCE(INT(_xlpm.p)),_xlpm.d,TRANSPOSE(_xlfn.SEQUENCE(INT(_xlpm.p))),_xlpm.cnt,MMULT(--(MOD(_xlpm.q,_xlpm.d)=0),_xlfn.SEQUENCE(INT(_xlpm.p),,1,0)),IF(SUM(--(MOD(_xlpm.p,_xlfn.SEQUENCE(INT(_xlpm.p)))=0))=2,SUM(--(_xlpm.cnt=2)),""))))}
A11: Lecture
A12: Seule la combinaison position 8 / signe − produit 227, qui est premier et occupe le rang 49.
A13: Les trois autres candidats sont composés : 221, 215 et 209.
C21: Position | D21: Terme | E21: Expression | G21: Position | H21: Terme | I21: Expression
C22: 1 | D22: t_a^1 | E22: t_a^1 | G22: 1 | H22: t_a^1 | I22: t_a^1
C23: 2 | D23: t_a^2 | E23: t_a^2 | G23: 2 | H23: t_a^2 | I23: t_a^2
C24: 3 | D24: t_a^3 | E24: t_a^3 | G24: 3 | H24: t_a^3 | I24: t_a^3
C25: 4 | D25: t_a^4 | E25: t_a^4 | G25: 4 | H25: t_a^4 | I25: t_a^4
C26: 5 | D26: t_a^5 | E26: t_a^5 | G26: 5 | H26: t_a^5 | I26: t_a^5
C27: 6 | D27: t_a^6 | E27: t_a^6 | G27: 6 | H27: t_a^6 | I27: t_a^6
C28: 7 | D28: t_a^7 | E28: t_a^7 | G28: 7 | H28: t_a^7 | I28: t_a^7
C29: 8 | D29: t_a^8 | E29: t_a^8 | G29: 8 | H29: t_a^8 - t_a^6 | I29: t_a^8 − t_a^6
C30: 9 | D30: t_a^9 - t_a^7 | E30: t_a^9 − t_a^7 | G30: 9 | H30: t_a^9 - t_a^7 | I30: t_a^9 − t_a^7
C31: 10 | D31: t_a^10 - t_a^8 | E31: t_a^10 − t_a^8 | G31: Somme | H31: Somme_A9 | I31: Somme_Suite_A_9
C32: Somme | D32: =_xlfn.TEXTJOIN(" + ",TRUE,D22:D31) -> t_a^1 + t_a^2 + t_a^3 + t_a^4 + t_a^5 + t_a^6 + t_a^7 + t_a^8 + t_a^9 - t_a^7 + t_a^10 - t_a^8 | E32: =_xlfn.TEXTJOIN(" + ",TRUE,E22:E31) -> t_a^1 + t_a^2 + t_a^3 + t_a^4 + t_a^5 + t_a^6 + t_a^7 + t_a^8 + t_a^9 − t_a^7 + t_a^10 − t_a^8 | H32: {=_xlfn.TEXTJOIN(" + ",TRUE,_xlfn._xlws.FILTER(H22:H31,(H22:H31<>"Somme_A9")*(H22:H31<>"—")))} -> t_a^1 + t_a^2 + t_a^3 + t_a^4 + t_a^5 + t_a^6 + t_a^7 + t_a^8 - t_a^6 + t_a^9 - t_a^7 | I32: {=_xlfn.TEXTJOIN(" + ",TRUE,_xlfn._xlws.FILTER(I22:I31,(H22:H31<>"Somme_A9")*(H22:H31<>"—")))} -> t_a^1 + t_a^2 + t_a^3 + t_a^4 + t_a^5 + t_a^6 + t_a^7 + t_a^8 − t_a^6 + t_a^9 − t_a^7
C34: Position | D34: Terme | E34: Expression formelle | G34: Position | H34: Terme | I34: Expression formelle
C35: 1 | D35: t_b^1 | E35: t_b^1 | G35: 1 | H35: t_b^1 | I35: t_b^1
C36: 2 | D36: t_b^2 | E36: t_b^2 | G36: 2 | H36: t_b^2 | I36: t_b^2
C37: 3 | D37: t_b^3 | E37: t_b^3 | G37: 3 | H37: t_b^3 | I37: t_b^3
C38: 4 | D38: t_b^4 | E38: t_b^4 | G38: 4 | H38: t_b^4 | I38: t_b^4
C39: 5 | D39: t_b^5 | E39: t_b^5 | G39: 5 | H39: t_b^5 | I39: t_b^5
C40: 6 | D40: t_b^7 | E40: t_b^7 | G40: 6 | H40: t_b^7 | I40: t_b^7
C41: 7 | D41: t_b^8 | E41: t_b^8 | G41: 7 | H41: t_b^8 | I41: t_b^8
C42: 8 | D42: t_b^9 | E42: t_b^9 | G42: 8 | H42: t_b^9 - t_b^7 | I42: (t_b^9 − t_b^7)
C43: 9 | D43: t_b^10 - t_b^8 | E43: (t_b^10 − t_b^8) | G43: 9 | H43: t_b^10 - t_b^8 | I43: (t_b^10 − t_b^8)
C44: 10 | D44: t_b^11 - t_b^9 | E44: (t_b^11 − t_b^9) | G44: Somme | H44: Somme_B9 | I44: Somme suite B₉
C45: Somme | D45: {=_xlfn.TEXTJOIN(" + ",TRUE,_xlfn._xlws.FILTER(D35:D44,D35:D44<>"—"))} -> t_b^1 + t_b^2 + t_b^3 + t_b^4 + t_b^5 + t_b^7 + t_b^8 + t_b^9 + t_b^10 - t_b^8 + t_b^11 - t_b^9 | E45: {=_xlfn.TEXTJOIN(" + ",TRUE,_xlfn._xlws.FILTER(E35:E44,D35:D44<>"—"))} -> t_b^1 + t_b^2 + t_b^3 + t_b^4 + t_b^5 + t_b^7 + t_b^8 + t_b^9 + (t_b^10 − t_b^8) + (t_b^11 − t_b^9) | H45: =_xlfn.TEXTJOIN(" + ",TRUE,H35:H43) -> t_b^1 + t_b^2 + t_b^3 + t_b^4 + t_b^5 + t_b^7 + t_b^8 + t_b^9 - t_b^7 + t_b^10 - t_b^8 | I45: =_xlfn.TEXTJOIN(" + ",TRUE,I35:I43) -> t_b^1 + t_b^2 + t_b^3 + t_b^4 + t_b^5 + t_b^7 + t_b^8 + (t_b^9 − t_b^7) + (t_b^10 − t_b^8)
C47: Option | D47: Position Digamma | E47: Terme Digamma | F47: Opération | G47: Forme concise | H47: Développement complet | I47: Statut
C48: 1 | D48: 7 | E48: t_a^7 | F48: + | G48: ="Somme_A10 "&F48&" "&E48 -> Somme_A10 + t_a^7 | H48: ="("&$E$32&") "&F48&" "&E48 -> (t_a^1 + t_a^2 + t_a^3 + t_a^4 + t_a^5 + t_a^6 + t_a^7 + t_a^8 + t_a^9 − t_a^7 + t_a^10 − t_a^8) + t_a^7 | I48: =IF(AND(D48=_xlfn.XLOOKUP(Parametres!$A$11,tblRegles[Rapport],tblRegles[Position Digamma]),F48=IF(_xlfn.XLOOKUP(Parametres!$A$11,tblRegles[Rapport],tblRegles[Signe Digamma])=1,"+","−")),"Option retenue pour "&Parametres!$A$11,"Candidate") -> Candidate
C49: 2 | D49: 7 | E49: t_a^7 | F49: − | G49: ="Somme_A10 "&F49&" "&E49 -> Somme_A10 − t_a^7 | H49: ="("&$E$32&") "&F49&" "&E49 -> (t_a^1 + t_a^2 + t_a^3 + t_a^4 + t_a^5 + t_a^6 + t_a^7 + t_a^8 + t_a^9 − t_a^7 + t_a^10 − t_a^8) − t_a^7 | I49: =IF(AND(D49=_xlfn.XLOOKUP(Parametres!$A$11,tblRegles[Rapport],tblRegles[Position Digamma]),F49=IF(_xlfn.XLOOKUP(Parametres!$A$11,tblRegles[Rapport],tblRegles[Signe Digamma])=1,"+","−")),"Option retenue pour "&Parametres!$A$11,"Candidate") -> Candidate
C50: 3 | D50: 8 | E50: t_a^8 | F50: + | G50: ="Somme_A10 "&F50&" "&E50 -> Somme_A10 + t_a^8 | H50: ="("&$E$32&") "&F50&" "&E50 -> (t_a^1 + t_a^2 + t_a^3 + t_a^4 + t_a^5 + t_a^6 + t_a^7 + t_a^8 + t_a^9 − t_a^7 + t_a^10 − t_a^8) + t_a^8 | I50: =IF(AND(D50=_xlfn.XLOOKUP(Parametres!$A$11,tblRegles[Rapport],tblRegles[Position Digamma]),F50=IF(_xlfn.XLOOKUP(Parametres!$A$11,tblRegles[Rapport],tblRegles[Signe Digamma])=1,"+","−")),"Option retenue pour "&Parametres!$A$11,"Candidate") -> Candidate
C51: 4 | D51: 8 | E51: t_a^8 | F51: − | G51: ="Somme_A10 "&F51&" "&E51 -> Somme_A10 − t_a^8 | H51: ="("&$E$32&") "&F51&" "&E51 -> (t_a^1 + t_a^2 + t_a^3 + t_a^4 + t_a^5 + t_a^6 + t_a^7 + t_a^8 + t_a^9 − t_a^7 + t_a^10 − t_a^8) − t_a^8 | I51: =IF(AND(D51=_xlfn.XLOOKUP(Parametres!$A$11,tblRegles[Rapport],tblRegles[Position Digamma]),F51=IF(_xlfn.XLOOKUP(Parametres!$A$11,tblRegles[Rapport],tblRegles[Signe Digamma])=1,"+","−")),"Option retenue pour "&Parametres!$A$11,"Candidate") -> Option retenue pour 1/3
...

Sheet Code Python
A1: Code Python du moteur convolutif
A2: Copiez la colonne Code dans un fichier .py. Le moteur lit les tables Excel, reconstruit P, teste la primalité et mesure les premiers encore non couverts.
A4: CODE
A5: Ligne | B5: Code
A6: 1 | B6: from dataclasses import dataclass
A7: 2 | B7: from math import isqrt
A8: 3
A9: 4 | B9: @dataclass(frozen=True)
A10: 5 | B10: class Constants:
A11: 6 | B11: alpha_a: float
A12: 7 | B12: alpha_b: float
A13: 8 | B13: offset_a: float
A14: 9 | B14: offset_b: float
A15: 10
A16: 11 | B16: CONSTANTS = {
A17: 12 | B17: 2: Constants(3.25, 6.5, 2, 66),
A18: 13 | B18: 3: Constants(73/9, 219/9, 1.5, 487*1.5),
A19: 14 | B19: 4: Constants(241/16, 964/16, 4/3, 3073*(4/3)),
A20: 15 | B20: }
A21: 16
A22: 17 | B22: def term_a(k, n, i, a1=None, small_model='XIII'):
A23: 18 | B23: a1 = k if a1 is None else a1
A24: 19 | B24: r = k
A25: 20 | B25: if not (k >= 2 and n >= 1 and 1 <= i <= n): return 0
A26: 21 | B26: if n <= 7 and small_model == 'XIII': return a1 * r**(i-1)
A27: 22 | B27: if n <= 7:
A28: 23 | B28: if i == 1: return a1
A29: 24 | B29: if n == 2 and i == 2: return a1 * (r - 1/r)
A30: 25 | B30: if n >= 3 and i <= n-2: return a1 * r**(i-1)
A31: 26 | B31: if i == n-1: return a1 * r**(n-3) * (r - 1/r)
A32: 27 | B32: return a1 * r**(n-3) * (r - 1/r) * r
A33: 28 | B33: if i == 1: return a1
... A36: 31 | B36: return (r - 1/r) * a1 * r**(n-2)
A37: 32
A38: 33 | B38: def term_b(k, n, i, a1=None, small_model='XIII'):
A39: 34 | B39: a1 = k if a1 is None else a1
A40: 35 | B40: r = k
A41: 36 | B41: if n <= 7: return term_a(k, n, i, a1, small_model)
A42: 37 | B42: if i == 1: return a1
A43: 38 | B43: if i <= 5: return a1 * r**(i-1)
...
